Workbook

Sheet P&L月次
A1: にからす 財務モデル v3.0 — P&L月次
A2: 期間: 2026年3月〜2027年2月（D30年間契約モデル）/ 単位: 万円
B4: FY通期 | C4: 3月 | D4: 4月 | E4: 5月 | F4: 6月 | G4: 7月 | H4: 8月 | I4: 9月 | J4: 10月 | K4: 11月 | L4: 12月 | M4: 1月 | N4: 2月
A6: 【A】売上前提（青=入力セル）
A7: ① 既存コンサル
A8: クライアント数（社） | B8: =SUM(C8:N8) | C8: 5 | D8: 5 | E8: 5 | F8: 5 | G8: 5 | H8: 5 | I8: 5 | J8: 5 | K8: 5 | L8: 5 | M8: 5 | N8: 5
A9: 平均月額単価（万円/社） | C9: 92 | D9: 92 | E9: 92 | F9: 92 | G9: 92 | H9: 92 | I9: 92 | J9: 92 | K9: 92 | L9: 92 | M9: 92 | N9: 92
A10: → 既存売上 | B10: =SUM(C10:N10) | C10: =C8*C9 | D10: =D8*D9 | E10: =E8*E9 | F10: =F8*F9 | G10: =G8*G9 | H10: =H8*H9 | I10: =I8*I9 | J10: =J8*J9 | ... N10: =N8*N9
A12: ② AI駆動開発（月額リテーナー）
A13: 契約社数（社） | C13: 1 | D13: 1 | E13: 1 | F13: 3 | G13: 3 | H13: 5 | I13: 5 | J13: 5 | K13: 5 | L13: 5 | M13: 5 | N13: 5
A14: 月額単価（万円/社） | C14: 60 | D14: 60 | E14: 60 | F14: 60 | G14: 60 | H14: 60 | I14: 60 | J14: 60 | K14: 60 | L14: 60 | M14: 60 | N14: 60
A15: → AI駆動売上 | B15: =SUM(C15:N15) | C15: =C13*C14 | D15: =D13*D14 | E15: =E13*E14 | F15: =F13*F14 | G15: =G13*G14 | H15: =H13*H14 | I15: =I13*I14 | J15: =J13*J14 | ... N15: =N13*N14
A17: ③ 中小DX（年間契約）
A18: 契約社数（社） | C18: 0 | D18: 0 | E18: 0 | F18: 1 | G18: 2 | H18: 2 | I18: 3 | J18: 4 | K18: 5 | L18: 5 | M18: 5 | N18: 5
A19: 月額換算単価（万円/社） | C19: 25 | D19: 25 | E19: 25 | F19: 25 | G19: 25 | H19: 25 | I19: 25 | J19: 25 | K19: 25 | L19: 25 | M19: 25 | N19: 25
A20: → 中小DX売上 | B20: =SUM(C20:N20) | C20: =C18*C19 | D20: =D18*D19 | E20: =E18*E19 | F20: =F18*F19 | G20: =G18*G19 | H20: =H18*H19 | I20: =I18*I19 | J20: =J18*J19 | ... N20: =N18*N19
A22: ④ Physical AI（年間契約）
A23: 契約社数（社） | C23: 0 | D23: 0 | E23: 0 | F23: 0 | G23: 1 | H23: 1 | I23: 1 | J23: 2 | K23: 2 | L23: 3 | M23: 3 | N23: 3
A24: 月額換算単価（万円/社） | C24: 42 | D24: 42 | E24: 42 | F24: 42 | G24: 42 | H24: 42 | I24: 42 | J24: 42 | K24: 42 | L24: 42 | M24: 42 | N24: 42
A25: → Physical AI売上 | B25: =SUM(C25:N25) | C25: =C23*C24 | D25: =D23*D24 | E25: =E23*E24 | F25: =F23*F24 | G25: =G23*G24 | H25: =H23*H24 | I25: =I23*I24 | J25: =J23*J24 | ... N25: =N23*N24
A27: ⑤ プロダクト（WazaAI年間契約）
A28: 契約社数（社） | C28: 0 | D28: 0 | E28: 0 | F28: 0 | G28: 0 | H28: 0 | I28: 0 | J28: 1 | K28: 1 | L28: 2 | M28: 2 | N28: 2
A29: 月額換算単価（万円/社） | C29: 25 | D29: 25 | E29: 25 | F29: 25 | G29: 25 | H29: 25 | I29: 25 | J29: 25 | K29: 25 | L29: 25 | M29: 25 | N29: 25
A30: → プロダクト売上 | B30: =SUM(C30:N30) | C30: =C28*C29 | D30: =D28*D29 | E30: =E28*E29 | F30: =F28*F29 | G30: =G28*G29 | H30: =H28*H29 | I30: =I28*I29 | J30: =J28*J29 | ... N30: =N28*N29
A32: 【売上合計】 | B32: =SUM(C32:N32) | C32: =C10+C15+C20+C25+C30 | D32: =D10+D15+D20+D25+D30 | E32: =E10+E15+E20+E25+E30 | F32: =F10+F15+F20+F25+F30 | G32: =G10+G15+G20+G25+G30 | H32: =H10+H15+H20+H25+H30 | I32: =I10+I15+I20+I25+I30 | J32: =J10+J15+J20+J25+J30 | ... N32: =N10+N15+N20+N25+N30
A33: （参考）D6四半期目標 | B33: 目標: 12,720 | C33: Q1: 1,560 | F33: Q2: 2,830 | I33: Q3: 3,560 | L33: Q4: 4,770
A35: 【B】コスト
A36: 小竹報酬（役員） | B36: =SUM(C36:N36) | C36: 60 | D36: 60 | E36: 60 | F36: 60 | G36: 60 | H36: 60 | I36: 60 | J36: 60 | K36: 60 | L36: 60 | M36: 60 | N36: 60
A37: 辻井報酬（業務委託・税込） | B37: =SUM(C37:N37) | C37: 82.5 | D37: 82.5 | E37: 82.5 | F37: 82.5 | G37: 82.5 | H37: 82.5 | I37: 82.5 | J37: 82.5 | K37: 82.5 | L37: 82.5 | M37: 82.5 | N37: 82.5
A38: ペリン報酬（業務委託） | B38: =SUM(C38:N38) | C38: 50 | D38: 50 | E38: 50 | F38: 50 | G38: 50 | H38: 50 | I38: 50 | J38: 50 | K38: 50 | L38: 50 | M38: 50 | N38: 50
A39: 森（ディプルメントPT・税込） | B39: =SUM(C39:N39) | C39: 115 | D39: 115 | E39: 115 | F39: 115 | G39: 115 | H39: 115 | I39: 115 | J39: 115 | K39: 115 | L39: 115 | M39: 115 | N39: 115
A40: 小林（業務委託） | B40: =SUM(C40:N40) | C40: 25 | D40: 25 | E40: 25 | F40: 25 | G40: 25 | H40: 25 | I40: 25 | J40: 25 | K40: 25 | L40: 25 | M40: 25 | N40: 25
A41: その他外注費 | B41: =SUM(C41:N41) | C41: 0 | D41: 0 | E41: 0 | F41: 0 | G41: 0 | H41: 0 | I41: 0 | J41: 0 | K41: 0 | L41: 0 | M41: 0 | N41: 0
A43: 社会保険（小竹分） | B43: =SUM(C43:N43) | C43: 14 | D43: 14 | E43: 14 | F43: 14 | G43: 14 | H43: 14 | I43: 14 | J43: 14 | K43: 14 | L43: 14 | M43: 14 | N43: 14
A44: オフィス | B44: =SUM(C44:N44) | C44: 5 | D44: 5 | E44: 5 | F44: 5 | G44: 5 | H44: 5 | I44: 5 | J44: 5 | K44: 5 | L44: 5 | M44: 5 | N44: 5
A45: ツール・サブスク | B45: =SUM(C45:N45) | C45: 5 | D45: 5 | E45: 5 | F45: 5 | G45: 5 | H45: 5 | I45: 5 | J45: 5 | K45: 5 | L45: 5 | M45: 5 | N45: 5
A46: 会計・税務（だんちゃん） | B46: =SUM(C46:N46) | C46: 3 | D46: 3 | E46: 3 | F46: 3 | G46: 3 | H46: 3 | I46: 3 | J46: 3 | K46: 3 | L46: 3 | M46: 3 | N46: 3
A47: その他固定費 | B47: =SUM(C47:N47) | C47: 2 | D47: 2 | E47: 2 | F47: 2 | G47: 2 | H47: 2 | I47: 2 | J47: 2 | K47: 2 | L47: 2 | M47: 2 | N47: 2
A49: 特別支出 | B49: =SUM(C49:N49) | C49: 40 | D49: 40 | E49: 40 | F49: 10 | G49: 20 | H49: 0 | I49: 0 | J49: 80 | K49: 0 | L49: 0 | M49: 0 | N49: 0
A50: 変動費（交通・出張等） | B50: =SUM(C50:N50) | C50: 8 | D50: 8 | E50: 8 | F50: 8 | G50: 8 | H50: 8 | I50: 8 | J50: 8 | K50: 8 | L50: 8 | M50: 8 | N50: 8
...

Sheet 人員計画
A1: 人員計画 — 月次コスト配分
A3: 氏名/役割 | B3: 契約形態 | C3: 月額（万円） | D3: 3月 | E3: 4月 | F3: 5月 | G3: 6月 | H3: 7月 | I3: 8月 | J3: 9月 | K3: 10月 | L3: 11月 | M3: 12月 | N3: 1月 | O3: 2月
A4: 小竹泉里（代表取締役） | B4: 役員報酬 | C4: 60 | D4: 1 | E4: 1 | F4: 1 | G4: 1 | H4: 1 | I4: 1 | J4: 1 | K4: 1 | L4: 1 | M4: 1 | N4: 1 | O4: 1
A5: 辻井敦生（CSO） | B5: 業務委託 | C5: 82.5 | D5: 1 | E5: 1 | F5: 1 | G5: 1 | H5: 1 | I5: 1 | J5: 1 | K5: 1 | L5: 1 | M5: 1 | N5: 1 | O5: 1
A6: ペリン（CTO） | B6: 業務委託 | C6: 50 | D6: 1 | E6: 1 | F6: 1 | G6: 1 | H6: 1 | I6: 1 | J6: 1 | K6: 1 | L6: 1 | M6: 1 | N6: 1 | O6: 1
A7: 森廣史（PM） | B7: 業務委託 | C7: 115 | D7: 1 | E7: 1 | F7: 1 | G7: 1 | H7: 1 | I7: 1 | J7: 1 | K7: 1 | L7: 1 | M7: 1 | N7: 1 | O7: 1
A8: 小林将太 | B8: 業務委託 | C8: 25 | D8: 1 | E8: 1 | F8: 1 | G8: 1 | H8: 1 | I8: 1 | J8: 1 | K8: 1 | L8: 1 | M8: 1 | N8: 1 | O8: 1
A9: （Year 2 エンジニア） | B9: 正社員（予定） | C9: 0 | D9: 0 | E9: 0 | F9: 0 | G9: 0 | H9: 0 | I9: 0 | J9: 0 | K9: 0 | L9: 0 | M9: 0 | N9: 0 | O9: 0
A10: 人件費合計（万円） | D10: =SUMPRODUCT($C$4:$C$9,D4:D9) | E10: =SUMPRODUCT($C$4:$C$9,E4:E9) | F10: =SUMPRODUCT($C$4:$C$9,F4:F9) | G10: =SUMPRODUCT($C$4:$C$9,G4:G9) | H10: =SUMPRODUCT($C$4:$C$9,H4:H9) | I10: =SUMPRODUCT($C$4:$C$9,I4:I9) | J10: =SUMPRODUCT($C$4:$C$9,J4:J9) | K10: =SUMPRODUCT($C$4:$C$9,K4:K9) | ... O10: =SUMPRODUCT($C$4:$C$9,O4:O9)
A12: 社保率（役員報酬に対して） | C12: 0.2
A13: 社保月額（万円） | D13: =$C$4*$C$12*D4 | E13: =$C$4*$C$12*E4 | F13: =$C$4*$C$12*F4 | G13: =$C$4*$C$12*G4 | H13: =$C$4*$C$12*H4 | I13: =$C$4*$C$12*I4 | J13: =$C$4*$C$12*J4 | K13: =$C$4*$C$12*K4 | ... O13: =$C$4*$C$12*O4

Sheet 予実管理
A1: 予実管理 — 計画 vs 実績
B3: FY通期 | C3: 3月 | D3: 4月 | E3: 5月 | F3: 6月 | G3: 7月 | H3: 8月 | I3: 9月 | J3: 10月 | K3: 11月 | L3: 12月 | M3: 1月 | N3: 2月
A5: 【計画】（P&Lシート参照）
A6: 売上合計 | B6: =SUM(C6:N6) | C6: ='P&L月次'!C32 | D6: ='P&L月次'!D32 | E6: ='P&L月次'!E32 | F6: ='P&L月次'!F32 | G6: ='P&L月次'!G32 | H6: ='P&L月次'!H32 | I6: ='P&L月次'!I32 | J6: ='P&L月次'!J32 | ... N6: ='P&L月次'!N32
A7: 既存コンサル | B7: =SUM(C7:N7) | C7: ='P&L月次'!C10 | D7: ='P&L月次'!D10 | E7: ='P&L月次'!E10 | F7: ='P&L月次'!F10 | G7: ='P&L月次'!G10 | H7: ='P&L月次'!H10 | I7: ='P&L月次'!I10 | J7: ='P&L月次'!J10 | ... N7: ='P&L月次'!N10
A8: AI駆動開発 | B8: =SUM(C8:N8) | C8: ='P&L月次'!C15 | D8: ='P&L月次'!D15 | E8: ='P&L月次'!E15 | F8: ='P&L月次'!F15 | G8: ='P&L月次'!G15 | H8: ='P&L月次'!H15 | I8: ='P&L月次'!I15 | J8: ='P&L月次'!J15 | ... N8: ='P&L月次'!N15
A9: 中小DX | B9: =SUM(C9:N9) | C9: ='P&L月次'!C20 | D9: ='P&L月次'!D20 | E9: ='P&L月次'!E20 | F9: ='P&L月次'!F20 | G9: ='P&L月次'!G20 | H9: ='P&L月次'!H20 | I9: ='P&L月次'!I20 | J9: ='P&L月次'!J20 | ... N9: ='P&L月次'!N20
A10: Physical AI | B10: =SUM(C10:N10) | C10: ='P&L月次'!C25 | D10: ='P&L月次'!D25 | E10: ='P&L月次'!E25 | F10: ='P&L月次'!F25 | G10: ='P&L月次'!G25 | H10: ='P&L月次'!H25 | I10: ='P&L月次'!I25 | J10: ='P&L月次'!J25 | ... N10: ='P&L月次'!N25
A11: プロダクト | B11: =SUM(C11:N11) | C11: ='P&L月次'!C30 | D11: ='P&L月次'!D30 | E11: ='P&L月次'!E30 | F11: ='P&L月次'!F30 | G11: ='P&L月次'!G30 | H11: ='P&L月次'!H30 | I11: ='P&L月次'!I30 | J11: ='P&L月次'!J30 | ... N11: ='P&L月次'!N30
A12: コスト合計 | B12: =SUM(C12:N12) | C12: ='P&L月次'!C52 | D12: ='P&L月次'!D52 | E12: ='P&L月次'!E52 | F12: ='P&L月次'!F52 | G12: ='P&L月次'!G52 | H12: ='P&L月次'!H52 | I12: ='P&L月次'!I52 | J12: ='P&L月次'!J52 | ... N12: ='P&L月次'!N52
A13: EBITDA | B13: =SUM(C13:N13) | C13: ='P&L月次'!C57 | D13: ='P&L月次'!D57 | E13: ='P&L月次'!E57 | F13: ='P&L月次'!F57 | G13: ='P&L月次'!G57 | H13: ='P&L月次'!H57 | I13: ='P&L月次'!I57 | J13: ='P&L月次'!J57 | ... N13: ='P&L月次'!N57
A14: 当期純利益 | B14: =SUM(C14:N14) | C14: ='P&L月次'!C62 | D14: ='P&L月次'!D62 | E14: ='P&L月次'!E62 | F14: ='P&L月次'!F62 | G14: ='P&L月次'!G62 | H14: ='P&L月次'!H62 | I14: ='P&L月次'!I62 | J14: ='P&L月次'!J62 | ... N14: ='P&L月次'!N62
A16: 【実績】★入力
A17: 売上合計（実績） | B17: =SUM(C17:N17)
A18: 既存コンサル | B18: =SUM(C18:N18)
A19: AI駆動開発 | B19: =SUM(C19:N19)
A20: 中小DX | B20: =SUM(C20:N20)
A21: Physical AI | B21: =SUM(C21:N21)
A22: プロダクト | B22: =SUM(C22:N22)
A23: コスト合計（実績） | B23: =SUM(C23:N23)
A24: EBITDA（実績） | B24: =SUM(C24:N24)
A25: 当期純利益（実績） | B25: =SUM(C25:N25)
A27: 【差異】（実績−計画）
A28: 売上差異 | B28: =SUM(C28:N28) | C28: =C17-C6 | D28: =D17-D6 | E28: =E17-E6 | F28: =F17-F6 | G28: =G17-G6 | H28: =H17-H6 | I28: =I17-I6 | J28: =J17-J6 | ... N28: =N17-N6
A29: コスト差異 | B29: =SUM(C29:N29) | C29: =C23-C12 | D29: =D23-D12 | E29: =E23-E12 | F29: =F23-F12 | G29: =G23-G12 | H29: =H23-H12 | I29: =I23-I12 | J29: =J23-J12 | ... N29: =N23-N12
A30: EBITDA差異 | B30: =SUM(C30:N30) | C30: =C24-C13 | D30: =D24-D13 | E30: =E24-E13 | F30: =F24-F13 | G30: =G24-G13 | H30: =H24-H13 | I30: =I24-I13 | J30: =J24-J13 | ... N30: =N24-N13
A31: 純利益差異 | B31: =SUM(C31:N31) | C31: =C25-C14 | D31: =D25-D14 | E31: =E25-E14 | F31: =F25-F14 | G31: =G25-G14 | H31: =H25-H14 | I31: =I25-I14 | J31: =J25-J14 | ... N31: =N25-N14

Sheet KPIツリー
A1: KPIツリー — 非財務指標トラッキング
B3: FY通期 | C3: 3月 | D3: 4月 | E3: 5月 | F3: 6月 | G3: 7月 | H3: 8月 | I3: 9月 | J3: 10月 | K3: 11月 | L3: 12月 | M3: 1月 | N3: 2月
A5: 【起点指標】
A6: DM送付数（通）【計画】 | B6: =SUM(C6:N6) | C6: 0 | D6: 0 | E6: 30 | F6: 30 | G6: 20 | H6: 20 | I6: 0 | J6: 0 | K6: 0 | L6: 0 | M6: 0 | N6: 0
A7: DM送付数（通）【実績】★ | B7: =SUM(C7:N7)
A8: 技術記事公開数（本）【計画】 | B8: =SUM(C8:N8) | C8: 2 | D8: 2 | E8: 2 | F8: 2 | G8: 2 | H8: 2 | I8: 2 | J8: 2 | K8: 2 | L8: 2 | M8: 2 | N8: 2
A9: 技術記事公開数（本）【実績】★ | B9: =SUM(C9:N9)
A10: 展示会出展【計画】 | B10: =SUM(C10:N10) | C10: 0 | D10: 0 | E10: 0 | F10: 0 | G10: 1 | H10: 0 | I10: 0 | J10: 1 | K10: 0 | L10: 0 | M10: 0 | N10: 0
A11: 展示会出展【実績】★ | B11: =SUM(C11:N11)
A12: 【中間指標】
A13: 税理士面談数（件）【計画】 | B13: =SUM(C13:N13) | C13: 0 | D13: 0 | E13: 0 | F13: 1 | G13: 1 | H13: 1 | I13: 1 | J13: 1 | K13: 0 | L13: 0 | M13: 0 | N13: 0
A14: 税理士面談数（件）【実績】★ | B14: =SUM(C14:N14)
A15: 問合せ件数【計画】 | B15: =SUM(C15:N15) | C15: 1 | D15: 1 | E15: 2 | F15: 2 | G15: 3 | H15: 3 | I15: 3 | J15: 3 | K15: 3 | L15: 3 | M15: 2 | N15: 2
A16: 問合せ件数【実績】★ | B16: =SUM(C16:N16)
A17: 展示会リード数【計画】 | B17: =SUM(C17:N17) | C17: 0 | D17: 0 | E17: 0 | F17: 0 | G17: 60 | H17: 0 | I17: 0 | J17: 50 | K17: 0 | L17: 0 | M17: 0 | N17: 0
A18: 展示会リード数【実績】★ | B18: =SUM(C18:N18)
A19: 商談数【計画】 | B19: =SUM(C19:N19) | C19: 0 | D19: 1 | E19: 1 | F19: 2 | G19: 3 | H19: 3 | I19: 3 | J19: 4 | K19: 3 | L19: 3 | M19: 2 | N19: 2
A20: 商談数【実績】★ | B20: =SUM(C20:N20)
A21: 【結果指標】
A22: 新規契約社数（累計）【計画】 | B22: =SUM(C22:N22) | C22: 1 | D22: 1 | E22: 1 | F22: 3 | G22: 5 | H22: 7 | I22: 9 | J22: 11 | K22: 13 | L22: 15 | M22: 15 | N22: 15
A23: 新規契約社数（累計）【実績】★ | B23: =SUM(C23:N23)
A24: 新規売上（万円）【計画】 | B24: =SUM(C24:N24) | C24: ='P&L月次'!C32-'P&L月次'!C10 | D24: ='P&L月次'!D32-'P&L月次'!D10 | E24: ='P&L月次'!E32-'P&L月次'!E10 | F24: ='P&L月次'!F32-'P&L月次'!F10 | G24: ='P&L月次'!G32-'P&L月次'!G10 | H24: ='P&L月次'!H32-'P&L月次'!H10 | I24: ='P&L月次'!I32-'P&L月次'!I10 | J24: ='P&L月次'!J32-'P&L月次'!J10 | ... N24: ='P&L月次'!N32-'P&L月次'!N10
A25: 新規売上（万円）【実績】★ | B25: =SUM(C25:N25)

Sheet CF計画
A1: CF計画 — キャッシュフロー月次
A2: 起点: 5月末 ¥100万（税金等支払後）
B4: FY通期 | C4: 3月 | D4: 4月 | E4: 5月 | F4: 6月 | G4: 7月 | H4: 8月 | I4: 9月 | J4: 10月 | K4: 11月 | L4: 12月 | M4: 1月 | N4: 2月
A6: 期首現預金 | C6: 0 | D6: 0 | E6: 100 | F6: =E18 | G6: =F18 | H6: =G18 | I6: =H18 | J6: =I18 | K6: =J18 | L6: =K18 | M6: =L18 | N6: =M18
A8: 【営業CF】
A9: 入金（売上） | B9: =SUM(C9:N9) | C9: ='P&L月次'!C32 | D9: ='P&L月次'!D32 | E9: ='P&L月次'!E32 | F9: ='P&L月次'!F32 | G9: ='P&L月次'!G32 | H9: ='P&L月次'!H32 | I9: ='P&L月次'!I32 | J9: ='P&L月次'!J32 | ... N9: ='P&L月次'!N32
A10: 出金（コスト） | B10: =SUM(C10:N10) | C10: =-'P&L月次'!C52 | D10: =-'P&L月次'!D52 | E10: =-'P&L月次'!E52 | F10: =-'P&L月次'!F52 | G10: =-'P&L月次'!G52 | H10: =-'P&L月次'!H52 | I10: =-'P&L月次'!I52 | J10: =-'P&L月次'!J52 | ... N10: =-'P&L月次'!N52
A11: 法人税・消費税（★入力） | B11: =SUM(C11:N11) | C11: 0 | D11: 0 | E11: 0 | F11: 0 | G11: 0 | H11: -200 | I11: 0 | J11: 0 | K11: 0 | L11: 0 | M11: 0 | N11: -200
A12: 売掛金変動（★入力） | B12: =SUM(C12:N12) | C12: 0 | D12: 0 | E12: 0 | F12: 0 | G12: 0 | H12: 0 | I12: 0 | J12: 0 | K12: 0 | L12: 0 | M12: 0 | N12: 0
A13: 営業CF小計 | B13: =SUM(C13:N13) | C13: =C9+C10+C11+C12 | D13: =D9+D10+D11+D12 | E13: =E9+E10+E11+E12 | F13: =F9+F10+F11+F12 | G13: =G9+G10+G11+G12 | H13: =H9+H10+H11+H12 | I13: =I9+I10+I11+I12 | J13: =J9+J10+J11+J12 | ... N13: =N9+N10+N11+N12
A15: 【投資CF】
A16: 設備投資・HW購入（★入力） | B16: =SUM(C16:N16) | C16: 0 | D16: 0 | E16: 0 | F16: 0 | G16: -30 | H16: 0 | I16: 0 | J16: 0 | K16: 0 | L16: -30 | M16: 0 | N16: 0
A18: 期末現預金 | B18: =N18 | C18: =C6+C13+C16 | D18: =D6+D13+D16 | E18: =E6+E13+E16 | F18: =F6+F13+F16 | G18: =G6+G13+G16 | H18: =H6+H13+H16 | I18: =I6+I13+I16 | J18: =J6+J13+J16 | ... N18: =N6+N13+N16
A20: 最低現預金ライン（目安） | C20: 100 | D20: 100 | E20: 100 | F20: 100 | G20: 100 | H20: 100 | I20: 100 | J20: 100 | K20: 100 | L20: 100 | M20: 100 | N20: 100
